<?xml version="1.0"?>
<robot name="furuta_pendulum">
  <material name="grey">
    <color rgba="0.8 0.8 0.8 1.0" />
  </material>

  <link drake_ignore="true" name="world" />
  <joint name="world_to_base_joint" type="fixed">
    <origin rpy="0.0 0.0 0.0" xyz="0.0 0.0 0.0" />
    <parent link="world" />
    <child link="base_link" />
  </joint>

  <link name="base_link">
    <visual>
      <origin rpy="0.0 0.0 0.0" xyz="0.0 0.0 0.0895" />
      <geometry>
        <cylinder length="0.179" radius="0.025" />
      </geometry>
      <material name="grey" />
    </visual>
    <!-- Collisions disabled, because I had problems getting drake's lqr to work - 
    when collisions are enabled it is necessary to use context with scene and plant, 
    without collisions it is sufficient to use only plant's context: 
    https://stackoverflow.com/questions/65471497/how-are-you-supposed-to-use-a-controller-with-a-urdf -->
    <!-- <collision>
      <origin rpy="0.0 0.0 0.0" xyz="0.0 0.0 0.0895" />
      <geometry>
        <cylinder length="0.179" radius="0.025" />
      </geometry>
    </collision> -->
    <inertial>
      <mass value="10.0" />
      <origin rpy="0.0 0.0 0.0" xyz="0.0 0.0 0.0" />
      <inertia ixx="0.1" ixy="0.0" ixz="0.0" iyy="0.1" iyz="0.0" izz="0.1" />
    </inertial>
  </link>

  <joint name="joint0" type="continuous">
    <origin rpy="0.0 0.0 0.0" xyz="0.0 0.0 0.184" />
    <parent link="base_link" />
    <child link="arm1" />
    <axis xyz="0 0 1" />
    <dynamics damping="0.0001" />
    <limit effort="4.0" velocity="15.0" />
  </joint>

  <link name="arm1">
    <visual>
      <origin rpy="0.0 1.5707963267948966 0.0" xyz="0.0467625 0.0 0.0" />
      <geometry>
        <cylinder length="0.093525" radius="0.005" />
      </geometry>
      <material name="grey" />
    </visual>
    <!-- <collision>
      <origin rpy="0.0 1.5707963267948966 0.0" xyz="0.0467625 0.0 0.0" />
      <geometry>
        <cylinder length="0.093525" radius="0.005" />
      </geometry>
    </collision> -->
    <inertial>
      <mass value="0.040466" />
      <origin rpy="0.0 0.0 0.0" xyz="0.05415 0.0 0.0" />
      <inertia ixx="1e-06" ixy="0.0" ixz="0.0" iyy="2.4054318e-05" iyz="0.0" izz="2.4054318e-05" />
    </inertial>
  </link>

  <joint name="joint1" type="continuous">
    <!-- -pi rotation so that for 0 pendulum is downward -->
    <origin rpy="-3.141592653589793 0.0 0.0" xyz="0.093525 0.0 0.0" />
    <parent link="arm1" />
    <child link="arm2" />
    <axis xyz="1 0 0" />
    <dynamics damping="1.7905703040590617e-05" />
    <limit effort="4.0" velocity="15.0" />
  </joint>

  <link name="arm2">
    <visual>
      <origin rpy="0.0 0.0 0.0" xyz="0.0 0.0 0.0645" />
      <geometry>
        <cylinder length="0.129" radius="0.005" />
      </geometry>
      <material name="grey" />
    </visual>
    <!-- <collision>
      <origin rpy="0.0 0.0 0.0" xyz="0.0 0.0 0.0645" />
      <geometry>
        <cylinder length="0.129" radius="0.005" />
      </geometry>
    </collision> -->
    <inertial>
      <mass value="0.009801" />
      <origin rpy="0.0 0.0 0.0" xyz="0.0 0.0 0.096608" />
      <inertia ixx="1.4790595e-05" ixy="0.0" ixz="0.0" iyy="1.4790595e-05" iyz="0.0" izz="1e-06" />
    </inertial>
  </link>

  <transmission name="joint0_trans" type="SimpleTransmission">
    <actuator name="joint0_actuator" />
    <joint name="joint0" />
    <mechanicalReduction>1</mechanicalReduction>
  </transmission>

  <!-- <transmission name="joint1_trans" type="SimpleTransmission">
    <actuator name="joint1_actuator" />
    <joint name="joint1" />
    <mechanicalReduction>1</mechanicalReduction>
  </transmission> -->
</robot>